<?xml version="1.0" encoding="utf-8"?>
<!-- This URDF was automatically created by SolidWorks to URDF Exporter! Originally created by Stephen Brawner (brawner@gmail.com) 
     Commit Version: 1.5.1-0-g916b5db  Build Version: 1.5.7152.31018
     For more information, please see http://wiki.ros.org/sw_urdf_exporter -->
<robot
  name="Bot">
  <link
    name="Chassis">
    <inertial>
      <origin
        xyz="0.073256350030413 0.0985099372490723 0.430048523355807"
        rpy="0 0 0" />
      <mass
        value="1.54875354069982" />
      <inertia
        ixx="0.0165047320422027"
        ixy="-2.70534209044293E-07"
        ixz="-3.96192161757293E-06"
        iyy="0.0390566352258776"
        iyz="8.5330907332849E-07"
        izz="0.0245928877731691" />
    </inertial>
    <visual>
      <origin
        xyz="0 0 0"
        rpy="0 0 0" />
      <geometry>
        <mesh
          filename="package://Bot/meshes/Chassis.STL" />
      </geometry>
      <material
        name="">
        <color
          rgba="0.792156862745098 0.819607843137255 0.933333333333333 1" />
      </material>
    </visual>
    <collision>
      <origin
        xyz="0 0 0"
        rpy="0 0 0" />
      <geometry>
        <mesh
          filename="package://Bot/meshes/Chassis.STL" />
      </geometry>
    </collision>
  </link>
  <link
    name="Power Bank">
    <inertial>
      <origin
        xyz="0.0732 0.0143850589491075 -3.27168847569226E-15"
        rpy="0 0 0" />
      <mass
        value="0.0975806283305884" />
      <inertia
        ixx="0.000105814469687505"
        ixy="7.18177618527732E-20"
        ixz="6.18149424782917E-18"
        iyy="0.000275305566297267"
        iyz="2.01073342630101E-17"
        izz="0.000178223607214106" />
    </inertial>
    <visual>
      <origin
        xyz="0 0 0"
        rpy="0 0 0" />
      <geometry>
        <mesh
          filename="package://Bot/meshes/Power Bank.STL" />
      </geometry>
      <material
        name="">
        <color
          rgba="0.792156862745098 0.819607843137255 0.933333333333333 1" />
      </material>
    </visual>
    <collision>
      <origin
        xyz="0 0 0"
        rpy="0 0 0" />
      <geometry>
        <mesh
          filename="package://Bot/meshes/Power Bank.STL" />
      </geometry>
    </collision>
  </link>
  <joint
    name="Power Bank Joint"
    type="fixed">
    <origin
      xyz="-0.023685 -0.50327 0.12851"
      rpy="1.5708 0 1.5713" />
    <parent
      link="Chassis" />
    <child
      link="Power Bank" />
    <axis
      xyz="0 0 0" />
  </joint>
  <link
    name="Battery">
    <inertial>
      <origin
        xyz="0 0.0212740041828206 -1.38777878078145E-16"
        rpy="0 0 0" />
      <mass
        value="0.0888686283305884" />
      <inertia
        ixx="5.47926091322645E-05"
        ixy="-3.50488228823458E-20"
        ixz="-3.10031264051815E-18"
        iyy="0.000181539941975464"
        iyz="-2.39997414663247E-19"
        izz="0.000154566450677174" />
    </inertial>
    <visual>
      <origin
        xyz="0 0 0"
        rpy="0 0 0" />
      <geometry>
        <mesh
          filename="package://Bot/meshes/Battery.STL" />
      </geometry>
      <material
        name="">
        <color
          rgba="0.792156862745098 0.819607843137255 0.933333333333333 1" />
      </material>
    </visual>
    <collision>
      <origin
        xyz="0 0 0"
        rpy="0 0 0" />
      <geometry>
        <mesh
          filename="package://Bot/meshes/Battery.STL" />
      </geometry>
    </collision>
  </link>
  <joint
    name="Battery Joint"
    type="fixed">
    <origin
      xyz="0.17262 -0.42993 0.12851"
      rpy="1.5708 0 1.5745" />
    <parent
      link="Chassis" />
    <child
      link="Battery" />
    <axis
      xyz="0 0 0" />
  </joint>
  <link
    name="Left Rear Wheel">
    <inertial>
      <origin
        xyz="0.017 -0.0400278959854739 0.0300554968703227"
        rpy="0 0 0" />
      <mass
        value="0.0161899157381337" />
      <inertia
        ixx="6.83865571850229E-06"
        ixy="-1.18158251659757E-21"
        ixz="-9.1775908525739E-22"
        iyy="5.80478743570855E-06"
        iyz="-1.90839648576411E-06"
        izz="5.4646444695116E-06" />
    </inertial>
    <visual>
      <origin
        xyz="0 0 0"
        rpy="0 0 0" />
      <geometry>
        <mesh
          filename="package://Bot/meshes/Left Rear Wheel.STL" />
      </geometry>
      <material
        name="">
        <color
          rgba="0.792156862745098 0.819607843137255 0.933333333333333 1" />
      </material>
    </visual>
    <collision>
      <origin
        xyz="0 0 0"
        rpy="0 0 0" />
      <geometry>
        <mesh
          filename="package://Bot/meshes/Left Rear Wheel.STL" />
      </geometry>
    </collision>
  </link>
  <joint
    name="Left Rear Wheel Joint"
    type="continuous">
    <origin
      xyz="0.27311 -0.53404 0.016515"
      rpy="-1.5708 0 3.1416" />
    <parent
      link="Chassis" />
    <child
      link="Left Rear Wheel" />
    <axis
      xyz="0 1 0" />
  </joint>
  <link
    name="Left Motor">
    <inertial>
      <origin
        xyz="0.0170000847357135 -0.0198397215207906 0.004152950727912"
        rpy="0 0 0" />
      <mass
        value="0.0628666055744514" />
      <inertia
        ixx="4.32925923240514E-05"
        ixy="8.45254418419363E-13"
        ixz="-1.73490163987075E-10"
        iyy="4.32245126404725E-05"
        iyz="-4.6037285428239E-07"
        izz="7.9488540067913E-06" />
    </inertial>
    <visual>
      <origin
        xyz="0 0 0"
        rpy="0 0 0" />
      <geometry>
        <mesh
          filename="package://Bot/meshes/Left Motor.STL" />
      </geometry>
      <material
        name="">
        <color
          rgba="0.792156862745098 0.819607843137255 0.933333333333333 1" />
      </material>
    </visual>
    <collision>
      <origin
        xyz="0 0 0"
        rpy="0 0 0" />
      <geometry>
        <mesh
          filename="package://Bot/meshes/Left Motor.STL" />
      </geometry>
    </collision>
  </link>
  <joint
    name="Left Motor Joint"
    type="continuous">
    <origin
      xyz="0 0 0"
      rpy="0 0 0" />
    <parent
      link="Left Rear Wheel" />
    <child
      link="Left Motor" />
    <axis
      xyz="0 1 0" />
  </joint>
  <link
    name="Left Round Wheel">
    <inertial>
      <origin
        xyz="0.017 -0.05 0.0600000000000001"
        rpy="0 0 0" />
      <mass
        value="0.156514146001844" />
      <inertia
        ixx="0.000103390636279718"
        ixy="1.11585948975329E-36"
        ixz="-6.95211497017247E-23"
        iyy="0.000103390636279718"
        iyz="1.66683754992319E-22"
        izz="0.000196346996159313" />
    </inertial>
    <visual>
      <origin
        xyz="0 0 0"
        rpy="0 0 0" />
      <geometry>
        <mesh
          filename="package://Bot/meshes/Left Round Wheel.STL" />
      </geometry>
      <material
        name="">
        <color
          rgba="0.792156862745098 0.819607843137255 0.933333333333333 1" />
      </material>
    </visual>
    <collision>
      <origin
        xyz="0 0 0"
        rpy="0 0 0" />
      <geometry>
        <mesh
          filename="package://Bot/meshes/Left Round Wheel.STL" />
      </geometry>
    </collision>
  </link>
  <joint
    name="Left Round Wheel Joint"
    type="continuous">
    <origin
      xyz="0 0.0370016062413412 0"
      rpy="0 0 0" />
    <parent
      link="Left Motor" />
    <child
      link="Left Round Wheel" />
    <axis
      xyz="0 1 0" />
  </joint>
  <link
    name="Right Rear Wheel">
    <inertial>
      <origin
        xyz="-0.0170000000000001 -0.0400278959854739 0.238055496870323"
        rpy="0 0 0" />
      <mass
        value="0.0161899157381337" />
      <inertia
        ixx="6.83865571850226E-06"
        ixy="-1.59927819397112E-21"
        ixz="1.34648782295458E-21"
        iyy="5.80478743570853E-06"
        iyz="-1.9083964857641E-06"
        izz="5.46464446951159E-06" />
    </inertial>
    <visual>
      <origin
        xyz="0 0 0"
        rpy="0 0 0" />
      <geometry>
        <mesh
          filename="package://Bot/meshes/Right Rear Wheel.STL" />
      </geometry>
      <material
        name="">
        <color
          rgba="0.792156862745098 0.819607843137255 0.933333333333333 1" />
      </material>
    </visual>
    <collision>
      <origin
        xyz="0 0 0"
        rpy="0 0 0" />
      <geometry>
        <mesh
          filename="package://Bot/meshes/Right Rear Wheel.STL" />
      </geometry>
    </collision>
  </link>
  <joint
    name="Right Rear Wheel Joint"
    type="continuous">
    <origin
      xyz="0.27311 -0.53404 0.016515"
      rpy="-1.5708 0 0" />
    <parent
      link="Chassis" />
    <child
      link="Right Rear Wheel" />
    <axis
      xyz="0 1 0" />
  </joint>
  <link
    name="Right Motor">
    <inertial>
      <origin
        xyz="-0.0169999152642865 -0.0198397215207906 0.004152950727912"
        rpy="0 0 0" />
      <mass
        value="0.0628666055744514" />
      <inertia
        ixx="4.32925923240514E-05"
        ixy="8.45254418423422E-13"
        ixz="-1.73490163987994E-10"
        iyy="4.32245126404724E-05"
        iyz="-4.60372854282388E-07"
        izz="7.94885400679129E-06" />
    </inertial>
    <visual>
      <origin
        xyz="0 0 0"
        rpy="0 0 0" />
      <geometry>
        <mesh
          filename="package://Bot/meshes/Right Motor.STL" />
      </geometry>
      <material
        name="">
        <color
          rgba="0.792156862745098 0.819607843137255 0.933333333333333 1" />
      </material>
    </visual>
    <collision>
      <origin
        xyz="0 0 0"
        rpy="0 0 0" />
      <geometry>
        <mesh
          filename="package://Bot/meshes/Right Motor.STL" />
      </geometry>
    </collision>
  </link>
  <joint
    name="Right Motor Joint"
    type="continuous">
    <origin
      xyz="0 0 0.208"
      rpy="0 0 0" />
    <parent
      link="Right Rear Wheel" />
    <child
      link="Right Motor" />
    <axis
      xyz="0 1 0" />
  </joint>
  <link
    name="Right Round Wheel">
    <inertial>
      <origin
        xyz="-0.017 -0.05 0.268"
        rpy="0 0 0" />
      <mass
        value="0.156514146001844" />
      <inertia
        ixx="0.000103390636279718"
        ixy="-1.94368867832977E-41"
        ixz="-6.65648952614325E-38"
        iyy="0.000103390636279718"
        iyz="-1.523220824894E-37"
        izz="0.000196346996159313" />
    </inertial>
    <visual>
      <origin
        xyz="0 0 0"
        rpy="0 0 0" />
      <geometry>
        <mesh
          filename="package://Bot/meshes/Right Round Wheel.STL" />
      </geometry>
      <material
        name="">
        <color
          rgba="0.792156862745098 0.819607843137255 0.933333333333333 1" />
      </material>
    </visual>
    <collision>
      <origin
        xyz="0 0 0"
        rpy="0 0 0" />
      <geometry>
        <mesh
          filename="package://Bot/meshes/Right Round Wheel.STL" />
      </geometry>
    </collision>
  </link>
  <joint
    name="Right Round Wheel Joint"
    type="continuous">
    <origin
      xyz="0 0.0370016062413412 -0.208"
      rpy="0 0 0" />
    <parent
      link="Right Motor" />
    <child
      link="Right Round Wheel" />
    <axis
      xyz="0 1 0" />
  </joint>
  <link
    name="Left Front Block">
    <inertial>
      <origin
        xyz="-0.019 0.016995 0.014"
        rpy="0 0 0" />
      <mass
        value="0.0498879953913404" />
      <inertia
        ixx="9.51260250780392E-06"
        ixy="-1.24029779000519E-21"
        ixz="-1.07289835214725E-21"
        iyy="1.25657196177918E-05"
        iyz="1.24231498930631E-21"
        izz="1.26592177473751E-05" />
    </inertial>
    <visual>
      <origin
        xyz="0 0 0"
        rpy="0 0 0" />
      <geometry>
        <mesh
          filename="package://Bot/meshes/Left Front Block.STL" />
      </geometry>
      <material
        name="">
        <color
          rgba="0.792156862745098 0.819607843137255 0.933333333333333 1" />
      </material>
    </visual>
    <collision>
      <origin
        xyz="0 0 0"
        rpy="0 0 0" />
      <geometry>
        <mesh
          filename="package://Bot/meshes/Left Front Block.STL" />
      </geometry>
    </collision>
  </link>
  <joint
    name="Left Front Block Joint"
    type="continuous">
    <origin
      xyz="-0.057887 -0.54304 0.034525"
      rpy="1.5708 0 0" />
    <parent
      link="Chassis" />
    <child
      link="Left Front Block" />
    <axis
      xyz="0 1 0" />
  </joint>
  <link
    name="Left Idler Wheel">
    <inertial>
      <origin
        xyz="-0.0357623798604737 -0.0250000535050624 0.0140006894928014"
        rpy="0 0 0" />
      <mass
        value="0.0523222325921473" />
      <inertia
        ixx="1.56126609879441E-05"
        ixy="-4.46507875660125E-06"
        ixz="-2.77887532391016E-10"
        iyy="1.40319252282098E-05"
        iyz="2.16112426363676E-11"
        izz="1.82361581162256E-05" />
    </inertial>
    <visual>
      <origin
        xyz="0 0 0"
        rpy="0 0 0" />
      <geometry>
        <mesh
          filename="package://Bot/meshes/Left Idler Wheel.STL" />
      </geometry>
      <material
        name="">
        <color
          rgba="0.792156862745098 0.819607843137255 0.933333333333333 1" />
      </material>
    </visual>
    <collision>
      <origin
        xyz="0 0 0"
        rpy="0 0 0" />
      <geometry>
        <mesh
          filename="package://Bot/meshes/Left Idler Wheel.STL" />
      </geometry>
    </collision>
  </link>
  <joint
    name="Left Idler Wheel Joint"
    type="continuous">
    <origin
      xyz="0 0 0"
      rpy="0 0 0" />
    <parent
      link="Left Front Block" />
    <child
      link="Left Idler Wheel" />
    <axis
      xyz="0 1 0" />
  </joint>
  <link
    name="Right Front Block">
    <inertial>
      <origin
        xyz="-0.0189999999999999 0.016995 -0.24"
        rpy="0 0 0" />
      <mass
        value="0.0498879953913404" />
      <inertia
        ixx="9.51260250780392E-06"
        ixy="-6.19140295352039E-22"
        ixz="-1.56385927765406E-21"
        iyy="1.25657196177918E-05"
        iyz="1.24231498930631E-21"
        izz="1.26592177473751E-05" />
    </inertial>
    <visual>
      <origin
        xyz="0 0 0"
        rpy="0 0 0" />
      <geometry>
        <mesh
          filename="package://Bot/meshes/Right Front Block.STL" />
      </geometry>
      <material
        name="">
        <color
          rgba="0.792156862745098 0.819607843137255 0.933333333333333 1" />
      </material>
    </visual>
    <collision>
      <origin
        xyz="0 0 0"
        rpy="0 0 0" />
      <geometry>
        <mesh
          filename="package://Bot/meshes/Right Front Block.STL" />
      </geometry>
    </collision>
  </link>
  <joint
    name="Right Front Block Joint"
    type="continuous">
    <origin
      xyz="-0.057887 -0.54304 0.034525"
      rpy="1.5708 0 0" />
    <parent
      link="Chassis" />
    <child
      link="Right Front Block" />
    <axis
      xyz="0 1 0" />
  </joint>
  <link
    name="Right Idler Wheel">
    <inertial>
      <origin
        xyz="-0.0357623798604737 -0.0250000535050624 -0.0139993105071985"
        rpy="0 0 0" />
      <mass
        value="0.0523222325921473" />
      <inertia
        ixx="1.56126609879441E-05"
        ixy="-4.46507875660125E-06"
        ixz="-2.77887532387518E-10"
        iyy="1.40319252282098E-05"
        iyz="2.16112426424398E-11"
        izz="1.82361581162257E-05" />
    </inertial>
    <visual>
      <origin
        xyz="0 0 0"
        rpy="0 0 0" />
      <geometry>
        <mesh
          filename="package://Bot/meshes/Right Idler Wheel.STL" />
      </geometry>
      <material
        name="">
        <color
          rgba="0.792156862745098 0.819607843137255 0.933333333333333 1" />
      </material>
    </visual>
    <collision>
      <origin
        xyz="0 0 0"
        rpy="0 0 0" />
      <geometry>
        <mesh
          filename="package://Bot/meshes/Right Idler Wheel.STL" />
      </geometry>
    </collision>
  </link>
  <joint
    name="Right Idler Wheel Joint"
    type="continuous">
    <origin
      xyz="0 0 -0.226"
      rpy="0 0 0" />
    <parent
      link="Right Front Block" />
    <child
      link="Right Idler Wheel" />
    <axis
      xyz="0 1 0" />
  </joint>
<link name="Hokoyu_laser_scan">
    <joint name="laser" type="fixed">
      <origin xyz="-200.073256350030413 0.0985099372490723 0.430048523355807" rpy="3.14159 0.0 0.0" />
      <parent link="Chassis" />
      <child link="Hokoyu_laser_scan" />
    </joint>

    <link name="Hokoyu_laser_scan">
      <visual>
        <geometry>
          <box size="0.00 0.05 0.06" />
        </geometry>
        <material name="Green" />
      </visual>
      <inertial>
        <mass value="0.000001" />
        <origin xyz="0 0 0" />
        <inertia ixx="0.0001" ixy="0.0" ixz="0.0"
          iyy="0.0001" iyz="0.0"
          izz="0.0001" />
      </inertial>
    </link>
</robot>